<?xml version="1.0"?>
<robot name="6_axis_arm">
	<link name="base_link">
		<visual>
			<geometry>
				<mesh filename="package://ros_learning/meshes/base_link_6.dae"/>
			</geometry>
		</visual>
	</link>
	<link name="link_1">
		<visual>
			<geometry>
				<mesh filename="package://ros_learning/meshes/link1_6.dae"/>
			</geometry>
		</visual>
	</link>
	<link name="link_2">
		<visual>
			<geometry>
				<mesh filename="package://ros_learning/meshes/link2_6.dae"/>
			</geometry>
		</visual>
	</link>
	<link name="link_3">
		<visual>
			<geometry>
				<mesh filename="package://ros_learning/meshes/link3_6.dae"/>
			</geometry>
		</visual>
	</link>
	<link name="link_4">
		<visual>
			<geometry>
				<mesh filename="package://ros_learning/meshes/link4_6.dae"/>
			</geometry>
		</visual>
	</link>
	<link name="link_5">
		<visual>
			<geometry>
				<mesh filename="package://ros_learning/meshes/link5_6.dae"/>
            </geometry>      
        </visual>
    </link>
    <link name="link_6">
    	<visual>
    		<geometry>
    			<mesh filename="package://ros_learning/meshes/link6_6.dae"/>
            </geometry>      
        </visual>
    </link>
    <link name="tool" />
    <joint name="joint_1" type="revolute">
    	<parent link="base_link" />
    	<child link="link_1" />
    	<origin rpy="0.000000 0.000000 0.000000" xyz="0.000000 0.000000 0.181500" />
    	<axis xyz="0.000000 0.000000 1.000000" />
    	<limit effort="300" lower="-1.57" upper="1.57" velocity="0.1" />
    </joint>
    <joint name="joint_2" type="revolute">
		<parent link="link_1" />
		<child link="link_2" />
		<origin rpy="0.000000 0.000000 0.000000" xyz="0.000000 0.000000 0.163500" />
		<axis xyz="0.000000 1.000000 0.000000" />
		<limit effort="300" lower="-1.57" upper="1.57" velocity="0.1" />
	</joint>
	<joint name="joint_3" type="revolute">
		<parent link="link_2" />
		<child link="link_3" />
		<origin rpy="0.000000 0.000000 0.000000" xyz="0.000000 0.000000 0.305000" />
		<axis xyz="0.000000 1.000000 0.000000" />
		<limit effort="300" lower="-1" upper="1" velocity="0.1" />
	</joint>
	<joint name="joint_4" type="revolute">
		<parent link="link_3" />
		<child link="link_4" />
		<origin rpy="0.000000 0.000000 0.000000" xyz="-0.010000 0.000000 0.164500" />
		<axis xyz="0.000000 0.000000 1.000000" />
		<limit effort="300" lower="-1.57" upper="1.57" velocity="0.1" />
	</joint>
	<joint name="joint_5" type="revolute">
		<parent link="link_4" />
		<child link="link_5" />
		<origin rpy="0.000000 0.000000 0.000000" xyz="0.000000 0.000000 0.135500" />
		<axis xyz="0.000000 1.000000 0.000000" />
		<limit effort="300" lower="-1.57" upper="1.57" velocity="0.1" />
	</joint>
	<joint name="joint_6" type="revolute">
		<parent link="link_5" />
		<child link="link_6" />
		<origin rpy="0.000000 0.000000 0.000000" xyz="0.000000 0.000000 0.070000" />
		<axis xyz="0.000000 0.000000 1.000000" />
		<limit effort="300" lower="-1.57" upper="1.57" velocity="0.1" />
	</joint>
	<joint name="tool_to_link6" type="fixed">
		<parent link="link_6"/>
		<child link="tool"/>
		<origin xyz="0 0 0"/>
    </joint>
</robot>

