<?xml version="1.0"?>

<robot name="scara">

  <link name="base_link">
    <visual>
      <geometry>
        <mesh filename="package://ros_learning/meshes/base_link.dae"/>
      </geometry>      
    </visual>
  </link>

  <link name="link_1">
  	<visual>
      <geometry>
        <mesh filename="package://ros_learning/meshes/link1.dae"/>
      </geometry>      
    </visual>
  </link>

  <link name="link_2">
  	<visual>
      <geometry>
        <mesh filename="package://ros_learning/meshes/link2.dae"/>
      </geometry>      
    </visual>
  </link>

  <link name="link_3">
  	<visual>
      <geometry>
        <mesh filename="package://ros_learning/meshes/link3.dae"/>
      </geometry>      
    </visual>
  </link>

  <link name="tool" />

  <joint name="link1_to_base" type="revolute">
    <parent link="base_link"/>
    <child link="link_1"/>
    <origin xyz="0.100 0 0.301"/>
    <axis xyz="0 0 1" />
    <limit effort="300" velocity="0.1" lower="-2.70" upper="2.70"/>
  </joint>

  <joint name="link2_to_link1" type="revolute">
    <parent link="link_1"/>
    <child link="link_2"/>
    <origin xyz="0.225 0 0.100"/>
    <axis xyz="0 0 1" />
    <limit effort="300" velocity="0.1" lower="-2.70" upper="2.70"/>
  </joint>

  <joint name="link3_to_link2" type="prismatic">
    <parent link="link_2"/>
    <child link="link_3"/>
    <origin xyz="0.225 0 0"/>
    <axis xyz="0 0 1" />
    <limit effort="300" velocity="0.1" lower="-0.225" upper="0"/>
  </joint>


  <joint name="tool_to_link3" type="fixed">
    <parent link="link_3"/>
    <child link="tool"/>
    <origin xyz="0 0 -0.175"/>
  </joint>    

</robot>